Workbook
Name ______DAT10: #REF!
Name ______DAT11: #REF!
Name ______DAT12: #REF!
Name ______DAT13: #REF!
Name ______DAT14: #REF!
Name ______DAT15: #REF!
Name ______DAT16: #REF!
Name ______DAT17: #REF!
Name ______DAT18: #REF!
Name ______DAT19: #REF!
Name ______DAT2: #REF!
Name ______DAT20: #REF!
Name ______DAT21: #REF!
Name ______DAT22: #REF!
Name ______DAT23: #REF!
Name ______DAT24: #REF!
Name ______DAT25: #REF!
Name ______DAT26: #REF!
Name ______DAT3: #REF!
Name ______DAT5: #REF!
Name ____DAT10: #REF!
Name ____DAT11: #REF!
Name ____DAT12: #REF!
Name ____DAT13: #REF!
Name ____DAT14: #REF!
Name ____DAT15: #REF!
Name ____DAT16: #REF!
Name ____DAT17: #REF!
Name ____DAT18: #REF!
Name ____DAT19: #REF!
Name ____DAT2: #REF!
Name ____DAT20: #REF!
Name ____DAT21: #REF!
Name ____DAT22: #REF!
Name ____DAT23: #REF!
Name ____DAT24: #REF!
Name ____DAT25: #REF!
Name ____DAT26: #REF!
Name ____DAT3: #REF!
Name ____DAT5: #REF!
Name ___DAT10: #REF!
Name ___DAT11: #REF!
Name ___DAT12: #REF!
Name ___DAT13: #REF!
Name ___DAT14: #REF!
Name ___DAT15: #REF!
Name ___DAT16: #REF!
Name ___DAT17: #REF!
Name ___DAT18: #REF!
Name ___DAT19: #REF!
Name ___DAT2: #REF!
Name ___DAT20: #REF!
Name ___DAT21: #REF!
Name ___DAT22: #REF!
Name ___DAT23: #REF!
Name ___DAT24: #REF!
Name ___DAT25: #REF!
Name ___DAT26: #REF!
Name ___DAT3: #REF!
Name ___DAT5: #REF!

Sheet INVOICE
B1: COMMERCIAL INVOICE | E1: SHEET NO; | F1: =C4 -> TY-260704K
A2: 1. Shipper/Exporter | C2: 8. No. & date of invoice
A3: TAE IL TRADING CO.,LTD
A4: 7F 715, DAERYUNG TECHNO TOWN 3 CHA | C4: TY-260704K | F4: 46207
A5: GASAN-DONG GEUMCHEON-GU,SEOUL,KOREA
A6: Tel : 02-858-0150 | C6: 9. No. & date of L/C
A7: Fax : 02-858-0152 | C7: T/T BASE
A8: 2. For Account & Risk of Messrs.
A9: # 0801381131 TAE IL VN COMPANY LIMITED
A10: #PHU TAI II HAMLET, AN THANH COMMUNE | C10: 10. L/ C issuing bank
A11: HAI PHONG CITY, VIET NAM
A12: TEL+84.02203.950.668 / 0975650029
A13: #phamthithuhoahpu@gmail.com (THU HOA)
A14: 3. Notify party
A16: SAME AS CONSIGNEE | C16: * FREIGHT PREPAID
C18: * CONSIGNED TO :
A19: 4. Port of loading | B19: 5. Final destination | C19: =A9 -> # 0801381131 TAE IL VN COMPANY LIMITED
C20: =A10 -> #PHU TAI II HAMLET, AN THANH COMMUNE
A21: INCHEON, KOREA | B21: HAIPHONG, VIETNAM | C21: =+A11 -> HAI PHONG CITY, VIET NAM
C22: =+A12 -> TEL+84.02203.950.668 / 0975650029
A23: 6. CARRIER | B23: 7. Sailing on or about
A24: DONGJIN CONTINENTAL / 0217W | B24: 46207 | C24: * WE CERTIFY THAT THERE IS NO WOOD
C25: PACKING MATERIAL IN THIS
C26: SHIPMENT
A27: 12. Marks and Numbers of PKGS | B27: 13. Description of goods | C27: 14. Quantity/unit | E27: 15.Unit-Price | F27: 16. Amount
E30: CIF HAIPHONG
B32: COUNTRY OF ORIGIN : KOREA
A34: STYLE NO | B34: DESCRIPTION | C34: QTY/YDS | E34: U/PRICE(USD) | F34: AMOUNT(USD) | N34: 원화단가 | O34: 환율 | P34: 1522.44
A35: BF6X27C51 | B35: 53" FOR THE FACE WOOL 98%, POLYURETHANE 2%(HS CODE: 6202.20.1000) | C35: 3950.44 | D35: MTS | E35: 1.5 | F35: =C35*E35 -> 5925.66 | G35: 겉감(국내분) | O35: =N35/$P$34 -> 0 | P35: =O35/$P$34 -> 0
B36: 44" LINING POLYESTER 100% | C36: 1409 | D36: MTS | E36: 1.04 | F36: =C36*E36 -> 1465.36 | G36: 비침방지(ASH:753M 국내분,140M 중국분,BR:446M 국내분, BR:70M 중국분 ) | N36: 1600 | O36: =N36/$P$34 -> 1.0509445
B37: 44" T/C LINING POLYESTER 100% | C37: 397 | D37: MTS | E37: 0.88 | F37: =C37*E37 -> 349.36 | G37: T/C(BK:220M, BR:132M 국내분, 45M 중국분, NA:77M 중국분) | N37: 1350 | O37: =N37/$P$34 -> 0.88673445
B38: E BAND 38MM | C38: 21 | D38: ROLL | E38: 0.39 | F38: =C38*E38 -> 8.19 | G38: 라이크라밴드(BK:19R 국내분, 2R 중국분, BR:4R 중국분) | N38: 600 | O38: =N38/$P$34 -> 0.3941042
B39: ZIPPER 9" | C39: 1835 | D39: EA | E39: 0.15 | F39: =C39*E39 -> 275.25 | G39: 에프론지퍼(BK:1020EA 국내분, 355EA 중국분,BR:610EA 국내분,205EA 중국분) | O39: =N39/$P$34 -> 0
B40: ZIPPER 10" | C40: 1735 | D40: EA | E40: 0.249 | F40: =C40*E40 -> 432.015 | G40: 혼솔지퍼(ASH:1090EA 국내분, 205EA 중국분, BR:645EA 국내분, 103EA 중국분) | N40: 380 | O40: =N40/$P$34 -> 0.24959933
A41: BF6X21C52 | B41: 52" FOR THE FACE POLYESTER 62%, RAYON 34%, POLYURETHANE 4%(HS CODE:6204.63.0000) | C41: 2226.35 | D41: MTS | E41: 1.5 | F41: =C41*E41 -> 3339.525 | G41: 겉감(국내분) | N41: 1400 | O41: =N41/$P$34 -> 0.91957647
B42: 44" T/C LINING POLYESTER 100% | C42: 600 | D42: MTS | E42: 0.88 | F42: =C42*E42 -> 528 | G42: T/C(IV:85M, BK:210M,ASH:252M 국내분,53M 중국분) | O42: =N42/$P$34 -> 0
B43: ZIPPER 9" | C43: 2645 | D43: EA | E43: 0.15 | F43: =C43*E43 -> 396.75 | G43: 에프론지퍼(BK:2240EA 국내분,255EA 중국분,IV:405EA 국내분) | N43: 240 | O43: =N43/$P$34 -> 0.15764168
A44: BF6X21C63 | B44: 58" FOR THE FACE COTTON 100%(HS CODE:6204.32.0000) | C44: 617.91 | D44: MTS | E44: 1.5 | F44: =C44*E44 -> 926.865 | G44: 겉감(국내분) | O44: =N44/$P$34 -> 0
B45: 44" LINING POLYESTER 100% | C45: 440 | D45: MTS | E45: 1.04 | F45: =C45*E45 -> 457.6 | G45: 비침방지(ASH:440M) | O45: =N45/$P$34 -> 0
B46: 44" T/C LINING POLYESTER 100% | C46: 110 | D46: MTS | E46: 0.886 | F46: =C46*E46 -> 97.46 | G46: T/C(ASH:91M 국내분,19M 중국분) | N46: 1350 | O46: =N46/$P$34 -> 0.88673445
...

Sheet Packing List
B1: PACKING LIST | F1: SHEET NO; | G1: =INVOICE!F1 -> TY-260704K
A2: 1. Shipper/Exporter | C2: 8. No. & date of invoice
A3: =INVOICE!A3 -> TAE IL TRADING CO.,LTD
A4: =INVOICE!A4 -> 7F 715, DAERYUNG TECHNO TOWN 3 CHA | C4: =INVOICE!C4 -> TY-260704K | G4: =INVOICE!F4 -> 46207
A5: =INVOICE!A5 -> GASAN-DONG GEUMCHEON-GU,SEOUL,KOREA
A6: =INVOICE!A6 -> Tel : 02-858-0150 | C6: 9.Remarks
A7: =INVOICE!A7 -> Fax : 02-858-0152
A8: 2. For Account & Risk of Messrs.
A9: # 0801381131 TAE IL VN COMPANY LIMITED
A10: #PHU TAI II HAMLET, AN THANH COMMUNE
A11: HAI PHONG CITY, VIET NAM
A12: TEL+84.02203.950.668 / 0975650029
A13: #phamthithuhoahpu@gmail.com (THU HOA)
A14: 3. Notify party | C14: * TOTAL N.NET WEIGHT | G14: KGS
C15: * TOTAL NET WEIGHT | F15: =D120 -> 5227.958 | G15: KGS
A16: SAME AS CONSIGNEE | C16: * TOTAL GROSS WEIGHT | F16: =D121 -> 5332.525 | G16: KGS
C17: * TOTAL MEASUREMENT | F17: =D122 -> 16 | G17: CBM
A19: 4. Port of loading | B19: 5. Final destination
A21: =INVOICE!A21:A21 -> INCHEON, KOREA | B21: HAIPHONG, VIETNAM
A23: 6. CARRIER | B23: 7. Sailing on or about
A24: =INVOICE!A24 -> DONGJIN CONTINENTAL / 0217W | B24: =INVOICE!B24 -> 46207
A27: 12. Marks and Numbers of PKGS | B27: 13. Description of goods | C27: 14. Quantity/unit | F27: 15.Unit-Price | G27: 16. Amount
F30: CIF HAIPHONG
M33: 0.064150943
A34: STYLE NO | B34: DESCRIPTION | C34: Q'TY/YDS | E34: N.W(KG) | F34: G.W(KG) | G34: No. & Kind Of Packages | J34: 단위무게 | K34: 포장번호
A35: =INVOICE!A35 -> BF6X27C51 | B35: =INVOICE!B35 -> 53" FOR THE FACE WOOL 98%, POLYURETHANE 2%(HS CODE: 6202.20.1000) | C35: =INVOICE!C35 -> 3950.44 | D35: =INVOICE!D35 -> MTS | E35: 1446 | F35: 1474.92 | G35: 52 | H35: BALE | I35: 빈폴 | N35: 빈폴 | O35: =SUMIFS(G35:G116,I35:I116,N35) -> 225
A36: =INVOICE!A36 -> 0 | B36: =INVOICE!B36 -> 44" LINING POLYESTER 100% | C36: =INVOICE!C36 -> 1409 | D36: =INVOICE!D36 -> MTS | E36: 95.812 | F36: 97.73 | G36: 5 | H36: BALE | I36: 자이언트 | K36: JT-1,JT-2,JT-3,JT-4,JT-5 | N36: 자이언트 | O36: =SUMIFS(G36:G117,I36:I117,N36) -> 33
A37: =INVOICE!A37 -> 0 | B37: =INVOICE!B37 -> 44" T/C LINING POLYESTER 100% | C37: =INVOICE!C37 -> 397 | D37: =INVOICE!D37 -> MTS | E37: 40.891 | F37: 41.71 | G37: 3 | H37: BALE | I37: 자이언트 | K37: JT-11,JT-13,JT-14 | N37: 다남 | O37: =SUMIFS(G37:G118,I37:I118,N37) -> 1
A38: =INVOICE!A38 -> 0 | B38: =INVOICE!B38 -> E BAND 38MM | C38: =INVOICE!C38 -> 21 | D38: =INVOICE!D38 -> ROLL | E38: 0.63 | F38: 0.64 | G38: 2 | H38: BOX | I38: 자이언트 | K38: JT-27,JT-32 | N38: 사무실 | O38: =SUMIFS(G38:G119,I38:I119,N38) -> 50
A39: =INVOICE!A39 -> 0 | B39: =INVOICE!B39 -> ZIPPER 9" | C39: =INVOICE!C39 -> 1835 | D39: =INVOICE!D39 -> EA | E39: 11.01 | F39: 11.23 | I39: 자이언트 | O39: =SUMIFS(G39:G120,I39:I120,N39) -> 0
A40: =INVOICE!A40 -> 0 | B40: =INVOICE!B40 -> ZIPPER 10" | C40: =INVOICE!C40 -> 1735 | D40: =INVOICE!D40 -> EA | E40: 8.675 | F40: 8.85 | G40: 1 | H40: BOX | I40: 자이언트 | K40: JT-31 | O40: =SUMIFS(G40:G121,I40:I121,N40) -> 0
A41: =INVOICE!A41 -> BF6X21C52 | B41: =INVOICE!B41 -> 52" FOR THE FACE POLYESTER 62%, RAYON 34%, POLYURETHANE 4%(HS CODE:6204.63.0000) | C41: =INVOICE!C41 -> 2226.35 | D41: =INVOICE!D41 -> MTS | E41: 1757.9 | F41: 1793.06 | G41: 82 | H41: BALE | I41: 빈폴 | O41: =SUMIFS(G41:G122,I41:I122,N41) -> 0
A42: =INVOICE!A42 -> 0 | B42: =INVOICE!B42 -> 44" T/C LINING POLYESTER 100% | C42: =INVOICE!C42 -> 600 | D42: =INVOICE!D42 -> MTS | E42: 61.8 | F42: 63.04 | G42: 3 | H42: BALE | I42: 자이언트 | K42: JT-10,JT-12,JT-15 | O42: =SUMIFS(G42:G123,I42:I123,N42) -> 0
A43: =INVOICE!A43 -> 0 | B43: =INVOICE!B43 -> ZIPPER 9" | C43: =INVOICE!C43 -> 2645 | D43: =INVOICE!D43 -> EA | E43: 15.87 | F43: 16.19 | G43: 1 | H43: BOX | I43: 자이언트 | K43: JT-30 | O43: =SUMIFS(G43:G124,I43:I124,N43) -> 0
A44: =INVOICE!A44 -> BF6X21C63 | B44: =INVOICE!B44 -> 58" FOR THE FACE COTTON 100%(HS CODE:6204.32.0000) | C44: =INVOICE!C44 -> 617.91 | D44: =INVOICE!D44 -> MTS | E44: 206.6 | F44: 210.73 | G44: 15 | H44: BALE | I44: 빈폴 | O44: =SUMIFS(G44:G125,I44:I125,N44) -> 0
A45: =INVOICE!A45 -> 0 | B45: =INVOICE!B45 -> 44" LINING POLYESTER 100% | C45: =INVOICE!C45 -> 440 | D45: =INVOICE!D45 -> MTS | E45: 29.92 | F45: 30.52 | G45: 1 | H45: BALE | I45: 자이언트 | J45: 68 | K45: JT-8
A46: =INVOICE!A46 -> 0 | B46: =INVOICE!B46 -> 44" T/C LINING POLYESTER 100% | C46: =INVOICE!C46 -> 110 | D46: =INVOICE!D46 -> MTS | E46: 11.33 | F46: 11.56 | G46: 1 | H46: BALE | I46: 자이언트 | J46: 103 | K46: JT-33
A47: =INVOICE!A47 -> 0 | B47: =INVOICE!B47 -> ZIPPER 9" | C47: =INVOICE!C47 -> 613 | D47: =INVOICE!D47 -> EA | E47: 3.68 | F47: =E47*1.02 -> 3.7536 | I47: 자이언트 | J47: 6
A48: =INVOICE!A48 -> BF6X21C62 | B48: =INVOICE!B48 -> 58 " FOR THE FACE COTTON 100%(HS CODE:6204.32.0000) | C48: =INVOICE!C48 -> 497.5 | D48: =INVOICE!D48 -> MTS | E48: 159.4 | F48: 162.59 | G48: 11 | H48: BALE | I48: 빈폴
A49: =INVOICE!A49 -> 0 | B49: =INVOICE!B49 -> 44"LINING POLYESTER 100% | C49: =INVOICE!C49 -> 604 | D49: =INVOICE!D49 -> MTS | E49: 41.07 | F49: 41.89 | G49: 3 | H49: BALE | I49: 자이언트 | J49: 68 | K49: JT-6,JT-7,JT-9
...

Sheet BEANPOLE_TTL
A1: 빈폴
E3: WIDTH
A4: NO | B4: SHIPPING DT. | C4: STYLE NO. | D4: COLOR | E4: CM | F4: INC | G4: R/N | H4: GROSS | I4: NET | J4: WEIGHT | K4: WT/MT | L4: THICKNESS | M4: THICKNESS/MT
A5: 1 | B5: 46216 | C5: BF6X27C51 | D5: 4 | E5: 133 | F5: =E5/2.512 -> 52.94586 | G5: 1 | H5: 83 | I5: 83 | J5: =I5*$K$40 -> 27.035831 | L5: =I5*$M$40 -> 22.710098
A6: 2 | G6: 2 | H6: 85 | I6: 85 | J6: =I6*$K$40 -> 27.687296 | L6: =I6*$M$40 -> 23.257329
A7: 3 | G7: 3 | H7: 87 | I7: 87 | J7: =I7*$K$40 -> 28.338762 | L7: =I7*$M$40 -> 23.80456
A8: 4 | G8: 4 | H8: 86 | I8: 86 | J8: =I8*$K$40 -> 28.013029 | L8: =I8*$M$40 -> 23.530945
A9: 5 | G9: 5 | H9: 85 | I9: 85 | J9: =I9*$K$40 -> 27.687296 | L9: =I9*$M$40 -> 23.257329
A10: 6 | G10: 6 | H10: 87 | I10: 87 | J10: =I10*$K$40 -> 28.338762 | L10: =I10*$M$40 -> 23.80456
A11: 7 | G11: 7 | H11: 102 | I11: 102 | J11: =I11*$K$40 -> 33.224756 | L11: =I11*$M$40 -> 27.908795
A12: 8 | G12: 8 | H12: 85 | I12: 85 | J12: =I12*$K$40 -> 27.687296 | L12: =I12*$M$40 -> 23.257329
A13: 9 | G13: 9 | H13: 87 | I13: 87 | J13: =I13*$K$40 -> 28.338762 | L13: =I13*$M$40 -> 23.80456
A14: 10 | G14: 10 | H14: 84 | I14: 83.75 | J14: =I14*$K$40 -> 27.28013 | L14: =I14*$M$40 -> 22.915309
A15: 11 | G15: 11 | H15: 85 | I15: 84.75 | J15: =I15*$K$40 -> 27.605863 | L15: =I15*$M$40 -> 23.188925
A16: 12 | G16: 12 | H16: 84 | I16: 83.75 | J16: =I16*$K$40 -> 27.28013 | L16: =I16*$M$40 -> 22.915309
A17: 13 | G17: 13 | H17: 88 | I17: 88 | J17: =I17*$K$40 -> 28.664495 | L17: =I17*$M$40 -> 24.078176
... A24: 20 | G24: 20 | H24: 82 | I24: 82 | J24: =I24*$K$40 -> 26.710098 | L24: =I24*$M$40 -> 22.436482
A25: 소계 | H25: =SUM(H5:H24) -> 1730 | I25: =SUM(I5:I24) -> 1728.25 | J25: =SUM(J5:J24) -> 562.94788 | L25: =I25*$M$40 -> 472.87622
A26: 1 | B26: 46216 | C26: BF6X27C51 | D26: D | E26: 133 | F26: =E26/2.512 -> 52.94586 | G26: 3 | H26: 82 | I26: 82 | J26: =I26*$K$40 -> 26.710098 | L26: =I26*$M$40 -> 22.436482
A27: 2 | G27: 4 | H27: 88 | I27: 87.75 | J27: =I27*$K$40 -> 28.583062 | L27: =I27*$M$40 -> 24.009772
A28: 3 | G28: 5 | H28: 86 | I28: 84 | J28: =I28*$K$40 -> 27.361564 | L28: =I28*$M$40 -> 22.983713
A29: 4 | G29: 6 | H29: 87 | I29: 87 | J29: =I29*$K$40 -> 28.338762 | L29: =I29*$M$40 -> 23.80456
A30: 5 | G30: 7 | H30: 91 | I30: 91 | J30: =I30*$K$40 -> 29.641694 | L30: =I30*$M$40 -> 24.899023
A31: 6 | G31: 11 | H31: 39 | I31: 36 | J31: =I31*$K$40 -> 11.726384 | L31: =I31*$M$40 -> 9.8501629
A32: 7 | G32: 13 | H32: 39 | I32: 38 | J32: =I32*$K$40 -> 12.37785 | L32: =I32*$M$40 -> 10.397394
A33: 8 | G33: 14 | H33: 84 | I33: 83.75 | J33: =I33*$K$40 -> 27.28013 | L33: =I33*$M$40 -> 22.915309
A34: 9 | G34: 21 | H34: 43 | I34: 42.75 | J34: =I34*$K$40 -> 13.925081 | L34: =I34*$M$40 -> 11.697068
A35: 10 | G35: 1 | H35: 44 | I35: 44 | J35: =I35*$K$40 -> 14.332248 | L35: =I35*$M$40 -> 12.039088
A36: 11 | G36: 5 | H36: 3.75 | I36: 3.75 | J36: =I36*$K$40 -> 1.2214984 | L36: =I36*$M$40 -> 1.0260586
A37: 12 | G37: 8 | H37: 87 | I37: 85 | J37: =I37*$K$40 -> 27.687296 | L37: =I37*$M$40 -> 23.257329
A38: 13 | G38: 9 | H38: 88 | I38: 88 | J38: =I38*$K$40 -> 28.664495 | L38: =I38*$M$40 -> 24.078176
A39: 14 | G39: 15 | H39: 87 | I39: 86.75 | J39: =I39*$K$40 -> 28.257329 | L39: =I39*$M$40 -> 23.736156
A40: 15 | G40: 18 | H40: 77 | I40: 76.75 | J40: 25 | K40: =J40/I40 -> 0.3257329 | L40: 21 | M40: =L40/I40 -> 0.27361564
A41: 16 | G41: 19 | H41: 8 | I41: 8 | J41: =I41*$K$40 -> 2.6058632 | L41: =I41*$M$40 -> 2.1889251
A42: 소계 | H42: =SUM(H26:H41) -> 1033.75 | I42: =SUM(I26:I41) -> 1024.5 | J42: =SUM(J26:J41) -> 333.71336 | K42: =SUM(K26:K41) -> 0.3257329 | L42: =SUM(L26:L41) -> 280.31922 | M42: =SUM(M26:M41) -> 0.27361564
A43: 품번별합계 | H43: =SUM(H42,H25) -> 2763.75 | I43: =SUM(I42,I25) -> 2752.75
A44: 1 | B44: 46216 | C44: BF6X21C52 | D44: 0 | E44: 131 | F44: =E44/2.512 -> 52.149682 | G44: 1 | H44: 48 | I44: 46 | J44: =I44*$K$54 -> 23.859341 | L44: =I44*$M$54 -> 24.769231
A45: 2 | G45: 2 | H45: 48.5 | I45: 46.5 | J45: =I45*$K$54 -> 24.118681 | L45: =I45*$M$54 -> 25.038462
A46: 3 | G46: 3 | H46: 48.75 | I46: 47 | J46: =I46*$K$54 -> 24.378022 | L46: =I46*$M$54 -> 25.307692
A47: 4 | G47: 4 | H47: 47.5 | I47: 45 | J47: =I47*$K$54 -> 23.340659 | L47: =I47*$M$54 -> 24.230769
...

Sheet SS_PAD

Sheet BEANPOLE_FOR CHINA
A15: 품번 | B15: 색상 | C15: 소재 | D15: 수량 | E15: 원단처 | F15: 단가 | G15: 폭 | H15: 혼용율 | I15: 가요척 | J15: 발주량
A16: BF6X21Y62 | B16: KHAKI | C16: 카도르 | D16: 200 | E16: 봅텍스타일 | F16: 24500 | G16: 143 | H16: AW 100% | I16: 1.25 | J16: 250 | K16: =ROUNDDOWN(D16/50,0) -> 4
A17: BF6X21C62 | B17: BROWN | C17: 카도르 | D17: 150 | E17: 봅텍스타일 | F17: 24500 | G17: 143 | H17: AW 100% | I17: 1.25 | J17: 188 | K17: =ROUNDDOWN(D17/50,0) -> 3
A18: BF6X21C63 | B18: ASH(#3562) | C18: 카도르 | D18: 100 | E18: 봅텍스타일 | F18: 24500 | G18: 143 | H18: AW 100% | I18: 1.29 | J18: 129 | K18: =ROUNDDOWN(D18/50,0) -> 2
A19: BF6964C23 | B19: ASH | C19: 데님체크 | D19: 250 | E19: 제니스에프엔에이 | F19: 9800 | G19: 106 | H19: C 100% | I19: 1.8 | J19: 450 | K19: =ROUNDDOWN(D19/50,0) -> 5
A20: BF6964C23 | B20: NAVY | C20: 데님체크 | D20: 300 | E20: 제니스에프엔에이 | F20: 9800 | G20: 106 | H20: C 100% | I20: 1.8 | J20: 540 | K20: =ROUNDDOWN(D20/50,0) -> 6
A21: BF6964C20 | B21: RED | C21: 미니타탄(JTF26-25) | D21: 300 | E21: 제니스에프엔에이 | F21: 9800 | G21: 106 | H21: C 100% | I21: 1.9 | J21: 570 | K21: =ROUNDDOWN(D21/50,0) -> 6
A22: BF6964C20 | B22: BLUE | C22: 미니타탄(JTF26-25) | D22: 250 | E22: 제니스에프엔에이 | F22: 9800 | G22: 106 | H22: C 100% | I22: 1.9 | J22: 475 | K22: =ROUNDDOWN(D22/50,0) -> 5
A23: BF6X27C51 | B23: ASH | C23: 멜리나 | D23: 200 | E23: 아즈텍 | F23: 19500 | G23: 133 | H23: AW 98%,PU2% | I23: 1.78 | J23: 356 | K23: =ROUNDDOWN(D23/50,0) -> 4
A24: BF6X27C51 | B24: BROWN | C24: 멜리나 | D24: 100 | E24: 아즈텍 | F24: 19500 | G24: 133 | H24: AW 98%,PU2% | I24: 1.78 | J24: 178 | K24: =ROUNDDOWN(D24/50,0) -> 2
A25: BF6827C51 | B25: NAVY | C25: 비엘라스트레치 | D25: 250 | E25: 아즈텍 | F25: 14000 | G25: 133 | H25: AW 48%,P 48, PU 4% | I25: 1.78 | J25: 545 | K25: =ROUNDDOWN(D25/50,0) -> 5

Sheet ZIPPER_DANAM
A2: TO : 태일
D3: PACKING LIST
A9: 업체명 : 다남인더스트리 | F9: 2026년 07월 8일
A10: C/T NO | B10: BRAND | C10: STYLE NO. | D10: ITEM | E10: 규격 | F10: COLOR | G10: Q'TY | H10: 비고 | I10: KG
A11: 1 | C11: LB6Y.JPM.192D | D11: 카라매칭 코아사 | F11: CA | G11: 1 | I11: 10
D12: 금속지퍼 | E12: 55 | F12: CA | G12: 78
E13: 66 | F13: CA | G13: 69
D14: 카라매칭 코아사 | F14: CC | G14: 1
D15: 금속지퍼 | E15: 55 | F15: CC | G15: 82
E16: 66 | F16: CC | G16: 70
A20: TTL | B20: C/T | I20: =SUM(I11:I18) -> 10 | J20: =SUM(J11:J18) -> 0

Sheet LABEL.TAG_MIDO
B1: 수출물품목록
B2: 입고일 | C2: 46210 | H2: 운송장번호
A4: 포장번호 | B4: 품번 | C4: 종류 | E4: 색상 | F4: 사이즈 | G4: 수량 | H4: 수령일자 | I4: =IF($B$1="수출물품목록","선적일자","입고일자") -> 선적일자 | J4: 비고
A5: T.I-176 | B5: LB6YJPM192D | C5: 메인라벨 | E5: CA | F5: 0 | G5: 78 | H5: 46210 | I5: 46221
C6: 케어라벨 | E6: CA | F6: 1 | G6: 69 | H6: 46210 | I6: 46221
C7: 이미지택 | E7: CC | F7: 0 | G7: 82 | H7: 46210 | I7: 46221
C8: 택고리 | E8: CC | F8: 1 | G8: 70 | H8: 46210 | I8: 46221
C9: 가격택
B11: VB6YJKM104Z | C11: 메인라벨 | E11: CA | F11: 0 | G11: 148 | H11: 46210 | I11: 46221
C12: 케어라벨 | E12: CA | F12: 1 | G12: 124 | H12: 46210 | I12: 46221
C13: 이미지택 | E13: CC | F13: 0 | G13: 110 | H13: 46210 | I13: 46221
C14: 택고리 | E14: CC | F14: 1 | G14: 96 | H14: 46210 | I14: 46221
C15: 이미지택2
C16: 가격택
B17: LB6YSLM192Z | C17: 메인라벨 | E17: CA | F17: 0 | G17: 53 | H17: 46210 | I17: 46221
C18: 케어라벨 | E18: CA | F18: 1 | G18: 41 | H18: 46210 | I18: 46221
C19: 이미지택 | E19: CC | F19: 0 | G19: 54 | H19: 46210 | I19: 46221
C20: 택고리 | E20: CC | F20: 1 | G20: 42 | H20: 46210 | I20: 46221
C21: 가격택
B23: LB6YJKM191Z | C23: 메인라벨 | E23: GR | F23: 0 | G23: 60 | H23: 46210 | I23: 46221
C24: 케어라벨 | E24: GR | F24: 1 | G24: 50 | H24: 46210 | I24: 46221
C25: 이미지택 | H25: 46210 | I25: 46221
C26: 택고리 | H26: 46210 | I26: 46221
C27: 가격택
B28: MB6YSLM115Z | C28: 메인라벨 | E28: DE | F28: 55 | G28: 260 | H28: 46210 | I28: 46221
C29: 케어라벨 | E29: DE | F29: 66 | G29: 270 | H29: 46210 | I29: 46221
C30: 이미지택 | E30: DE | F30: 77 | G30: 84 | H30: 46210 | I30: 46221
C31: 택고리 | E31: BR | F31: 55 | G31: 260 | H31: 46210 | I31: 46221
C32: 가격택 | E32: BR | F32: 66 | G32: 280 | H32: 46210 | I32: 46221
E33: BR | F33: 77 | G33: 85 | H33: 46210 | I33: 46221
E34: DG | F34: 55 | G34: 300 | H34: 46210 | I34: 46221
E35: DG | F35: 66 | G35: 320 | H35: 46210 | I35: 46221
E36: DG | F36: 77 | G36: 107 | H36: 46210 | I36: 46221
A37: T.I-175 | B37: VB6YJKM191Z | C37: 메인라벨 | E37: GR | F37: 0 | G37: 54 | H37: 46210 | I37: 46221
C38: 케어라벨 | E38: GR | F38: 1 | G38: 48 | H38: 46210 | I38: 46221
C39: 이미지택
C40: 택고리
C41: 가격택
B43: LB6YSKM191Z | C43: 메인라벨 | E43: GR | F43: 0 | G43: 60 | H43: 46210 | I43: 46221
C44: 케어라벨 | E44: GR | F44: 1 | G44: 48 | H44: 46210 | I44: 46221
...

Sheet LINING_SB
C1: SEONGBO TEXTILE CO.,LTD
A2: #102,SEONGBO BLDG. 19,NONHYUN-DONG,GANGNAM-GU,SEOUL,KOREA.
A3: TEL: (02) 545-1112, FAX: (02) 541-1112
A6: PACKING LIST
A7: CLIENT | D7: : | E7: 성보섬유상사(유) | L7: BUYER | N7: : | O7: 태일무역 <미도>
A8: COMMODITY | D8: : | E8: LINNING | L8: 입고처 | N8: :
A9: FINISHED | D9: : | E9: PD | L9: ORD Q'TY | N9: : | O9: 216
A10: DATE | D10: : | E10: 46218 | L10: SHPD Q'TY | N10: : | O10: 216
A11: WEIGHT | D11: : | E11: 216 | L11: CBM | N11: : | O11: 0.089
A13: COLOR ASSORT
A14: STYLE NO. | E14: ITEM | J14: COLOR NO. | L14: COLOR | N14: ORD Q'TY | P14: SHPD Q'TY | R14: LOSS
A15: MB6YSLM115Z | E15: 모니카(베이스) | F15: 모니카(베이스) | G15: 모니카(베이스) | H15: 모니카(베이스) | I15: 모니카(베이스) | J15: 뒤#7 | K15: 뒤#7 | L15: D/BEIGE | M15: D/BEIGE | N15: 50 | P15: 50
E16: 크루즈(골드컴퍼니) | F16: 크루즈(골드컴퍼니) | G16: 크루즈(골드컴퍼니) | H16: 크루즈(골드컴퍼니) | I16: 크루즈(골드컴퍼니) | J16: #10 | K16: #10 | L16: BROWN | M16: BROWN | N16: 50 | P16: 50
A17: MB6YSLM114Z | B17: MB6YSLM114Z | C17: MB6YSLM114Z | D17: MB6YSLM114Z | E17: 모니카(베이스) | F17: 모니카(베이스) | G17: 모니카(베이스) | H17: 모니카(베이스) | I17: 모니카(베이스) | J17: 뒤#7 | K17: 뒤#7 | L17: D/BEIGE | M17: D/BEIGE | N17: 24 | P17: 24
A18: LB6YJPM192D | E18: 덤부링(예나텍스) | J18: #73 | K18: #73 | L18: CAMEL | M18: CAMEL | N18: 18 | P18: 18
J19: #47 | K19: #47 | L19: CHARCOAL | M19: CHARCOAL | N19: 19 | P19: 19
E20: POLY 75/75 TWILL | F20: POLY 75/75 TWILL | G20: POLY 75/75 TWILL | H20: POLY 75/75 TWILL | I20: POLY 75/75 TWILL | J20: #9 | K20: #9 | L20: CAMEL | M20: CAMEL | N20: 27 | P20: 27
E21: POLY 50/75 TWILL | F21: POLY 50/75 TWILL | G21: POLY 50/75 TWILL | H21: POLY 50/75 TWILL | I21: POLY 50/75 TWILL | J21: #BK | K21: #BK | L21: CHARCOAL | M21: CHARCOAL | N21: 28 | P21: 28
A22: TOTAL | N22: =SUM(N15:N21) -> 216 | P22: =SUM(P15:P21) -> 216 | R22: =SUM(R15:R21) -> 0
A23: DETAIL PACKING
A24: C/T NO. | C24: COLOR | G24: 1 | H24: 2 | I24: 3 | J24: 4 | K24: 5 | L24: 6 | M24: 7 | N24: 8 | O24: 9 | P24: 10 | Q24: ROLL | R24: Q'TY
A25: SB-1 | C25: MB6YSLM115Z MB6YSLM114Z 뒤#7 | G25: 74 | Q25: =COUNT(G25:P25) -> 1 | R25: =SUM(G25:P25) -> 74
A26: SB-2 | C26: MB6YSLM115Z #10 | G26: 50 | Q26: =COUNT(G26:P26) -> 1 | R26: =SUM(G26:P26) -> 50
A27: SB-3 | C27: LB6YJPM192D #73 | G27: 18 | Q27: =COUNT(G27:P27) -> 1 | R27: =SUM(G27:P27) -> 18
A28: SB-4 | C28: LB6YJPM192D #47 | G28: 19 | Q28: =COUNT(G28:P28) -> 1 | R28: =SUM(G28:P28) -> 19
A29: SB-5 | C29: LB6YJPM192D #9 | G29: 27 | Q29: =COUNT(G29:P29) -> 1 | R29: =SUM(G29:P29) -> 27
C30: LB6YJPM192D #BK | G30: 28 | Q30: =COUNT(G30:P30) -> 1 | R30: =SUM(G30:P30) -> 28
G31: TOTAL: | I31: =COUNTA(A25:B30) -> 5 | J31: C/T | Q31: =SUM(Q25:Q30) -> 6 | R31: =SUM(R25:R30) -> 216

Sheet 제니스_중국분1
B1: 출고송장 (260615-2019,상차-1) | BY1: 상 호 | CH1: (주)케이에스케이대구지점
A6: 매 출 처 | K6: (주)제니스에프앤에이 | AQ6: 오 다 량 | BA6: 990.00 Mts
BY7: 등록번호 | CH7: 503-85-11473 | DB7: 성 명 | DH7: 고한식
A9: 오다번호 스타일NO | K9: 4502907396_x000D_ BF6964C23 | AQ9: 출 고 량 | BA9: 992.00 Mts
BY11: 주 소 | CH11: 대구광역시 서구 와룡로 70길 16-6
A13: 품 명 | K13: F12-BF6C16 CT 100 | AQ13: 오다/검사폭 | BA13: 106.00/111.00 Cm
A17: 바 이 어 | K17: 삼성물산-완사 | AQ17: 포장방법 | BA17: 이중비닐 | BY17: 업 태 | CH17: 제조 | CU17: 종 목 | DB17: 정포 임가공
A20: 인 수 처 | AQ20: 출 고 일 | BA20: 2026-07-14 | BY20: 전화번호 | CH20: 053)562-3410 FAX;053)562-0437
A23: 비 고 | K23: / 태일무역/효성 (0707) | DL23: Page : 1 / 1
A27: Color Name | AC27: Roll | AH27: Gross | AR27: Net | BB27: Loss | BI27: Weight
A30: 1 )4 재색 ASH | AC30: 9 | AH30: 450 | AR30: 450 | BI30: 64.75
A33: 2 )R 남색 NAVY | AC33: 13 | AH33: 544 | AR33: 542 | BB33: 2 | BI33: 78.1
A36: T O T A L --> | AC36: 22 | AH36: 994 | AR36: 992 | BB36: 2 | BI36: 142.85
A39: Color Name | AC39: Roll | AH39: Gross | AR39: Net | BB39: Loss | BI39: Weight | BS39: CT/No | BZ39: R/No | CF39: Lot | CM39: Gross | CV39: Net | DE39: Loss | DL39: Grade | DQ39: Weight
A42: 1 )4 재색 ASH | AC42: 9 | AH42: 450 | AR42: 450 | BI42: 64.75 | BZ42: 1 | CF42: 1 | CM42: 51 | CV42: 51 | DL42: A | DQ42: 7.45
BZ45: 2 | CF45: 1 | CM45: 31 | CV45: 31 | DL45: A | DQ45: 4.15
BZ48: 3 | CF48: 1 | CM48: 54 | CV48: 54 | DL48: A | DQ48: 7.95
BZ51: 4 | CF51: 1 | CM51: 53 | CV51: 53 | DL51: A | DQ51: 7.65
BZ54: 5 | CF54: 1 | CM54: 51 | CV54: 51 | DL54: A | DQ54: 7.55
BZ57: 6 | CF57: 1 | CM57: 56 | CV57: 56 | DL57: A | DQ57: 7.75
BZ60: 7 | CF60: 1 | CM60: 51 | CV60: 51 | DL60: A | DQ60: 7.15
BZ63: 8 | CF63: 1 | CM63: 52 | CV63: 52 | DL63: A | DQ63: 7.55
BZ66: 9 | CF66: 1 | CM66: 51 | CV66: 51 | DL66: A | DQ66: 7.55
A69: 2 )R 남색 NAVY | AC69: 13 | AH69: 544 | AR69: 542 | BB69: 2 | BI69: 78.1 | BZ69: 1 | CF69: 1 | CM69: 30 | CV69: 30 | DL69: A | DQ69: 4.45
BZ72: 2 | CF72: 1 | CM72: 46 | CV72: 46 | DL72: A | DQ72: 6.95
BZ75: 4 | CF75: 1 | CM75: 16 | CV75: 14 | DE75: 2 | DL75: A | DQ75: 2.7
BZ78: 5 | CF78: 1 | CM78: 42 | CV78: 42 | DL78: A | DQ78: 6.15
BZ81: 6 | CF81: 1 | CM81: 31 | CV81: 31 | DL81: A | DQ81: 4.25
BZ84: 7 | CF84: 1 | CM84: 52 | CV84: 52 | DL84: A | DQ84: 7.35
BZ87: 8 | CF87: 1 | CM87: 68 | CV87: 68 | DL87: A | DQ87: 9.65
BZ90: 9 | CF90: 1 | CM90: 46 | CV90: 46 | DL90: A | DQ90: 6.7
BZ93: 10 | CF93: 1 | CM93: 48 | CV93: 48 | DL93: A | DQ93: 6.7
BZ96: 11 | CF96: 1 | CM96: 55 | CV96: 55 | DL96: A | DQ96: 8.05
BZ99: 12 | CF99: 1 | CM99: 23 | CV99: 23 | DL99: A | DQ99: 3.15
BZ102: 13 | CF102: 1 | CM102: 30 | CV102: 30 | DL102: A | DQ102: 4.15
BZ105: 14 | CF105: 1 | CM105: 57 | CV105: 57 | DL105: A | DQ105: 7.85
A126: (주)유일전산 ☎ (02) 761-0758 섬유업체 S/W 개발전문업체 | BP126: 출력자 : 김희정 2026-07-14 오전 9:41:29

Sheet 제니스_중국분2
B1: 출고송장 (260626-2003,상차-1) | BY1: 상 호 | CH1: (주)케이에스케이대구지점
A6: 매 출 처 | K6: (주)제니스에프앤에이 | AQ6: 오 다 량 | BA6: 1,045.00 Mts
BY7: 등록번호 | CH7: 503-85-11473 | DB7: 성 명 | DH7: 고한식
A9: 오다번호 스타일NO | K9: 4502940779_x000D_ BF6964C20 | AQ9: 출 고 량 | BA9: 1,091.00 Mts
BY11: 주 소 | CH11: 대구광역시 서구 와룡로 70길 16-6
A13: 품 명 | K13: F12-BF6D05 CT 100 | AQ13: 오다/검사폭 | BA13: 106.00/113.00 Cm
A17: 바 이 어 | K17: 삼성물산-완사 | AQ17: 포장방법 | BA17: 이중비닐 | BY17: 업 태 | CH17: 제조 | CU17: 종 목 | DB17: 정포 임가공
A20: 인 수 처 | AQ20: 출 고 일 | BA20: 2026-07-14 | BY20: 전화번호 | CH20: 053)562-3410 FAX;053)562-0437
A23: 비 고 | K23: / 태일무역/효성 (0603) | DL23: Page : 1 / 1
A27: Color Name | AC27: Roll | AH27: Gross | AR27: Net | BB27: Loss | BI27: Weight
A30: 1 )6 빨간색 RED | AC30: 7 | AH30: 616 | AR30: 615.25 | BB30: 0.75 | BI30: 84.25
A33: 2 )M 녹색 GREEN | AC33: 6 | AH33: 476 | AR33: 475.75 | BB33: 0.25 | BI33: 66.9
A36: T O T A L --> | AC36: 13 | AH36: 1092 | AR36: 1091 | BB36: 1 | BI36: 151.15
A39: Color Name | AC39: Roll | AH39: Gross | AR39: Net | BB39: Loss | BI39: Weight | BS39: CT/No | BZ39: R/No | CF39: Lot | CM39: Gross | CV39: Net | DE39: Loss | DL39: Grade | DQ39: Weight
A42: 1 )6 빨간색 RED | AC42: 7 | AH42: 616 | AR42: 615.25 | BB42: 0.75 | BI42: 84.25 | BZ42: 1 | CF42: 1 | CM42: 47 | CV42: 47 | DL42: A | DQ42: 6.45
BZ45: 2 | CF45: 1 | CM45: 76 | CV45: 75.75 | DE45: 0.25 | DL45: A | DQ45: 10.45
BZ48: 3 | CF48: 1 | CM48: 106 | CV48: 106 | DL48: A | DQ48: 14.4
BZ51: 4 | CF51: 1 | CM51: 111 | CV51: 111 | DL51: A | DQ51: 15.2
BZ54: 5 | CF54: 1 | CM54: 138 | CV54: 137.5 | DE54: 0.5 | DL54: A | DQ54: 18.9
BZ57: 6 | CF57: 1 | CM57: 93 | CV57: 93 | DL57: A | DQ57: 12.6
BZ60: 7 | CF60: 1 | CM60: 45 | CV60: 45 | DL60: A | DQ60: 6.25
A63: 2 )M 녹색 GREEN | AC63: 6 | AH63: 476 | AR63: 475.75 | BB63: 0.25 | BI63: 66.9 | BZ63: 1 | CF63: 1 | CM63: 47 | CV63: 47 | DL63: A | DQ63: 6.9
BZ66: 2 | CF66: 1 | CM66: 107 | CV66: 107 | DL66: A | DQ66: 14.85
BZ69: 3 | CF69: 1 | CM69: 48 | CV69: 48 | DL69: A | DQ69: 6.85
BZ72: 4 | CF72: 1 | CM72: 100 | CV72: 99.75 | DE72: 0.25 | DL72: A | DQ72: 14.3
BZ75: 5 | CF75: 1 | CM75: 139 | CV75: 139 | DL75: A | DQ75: 19.2
BZ78: 6 | CF78: 1 | CM78: 35 | CV78: 35 | DL78: A | DQ78: 4.8
A126: (주)유일전산 ☎ (02) 761-0758 섬유업체 S/W 개발전문업체 | BP126: 출력자 : 김희정 2026-07-14 오전 9:42:55

Sheet 자이언트
A1: 패킹리스트
A3: C/T NO | B3: STYLE NO | C3: 자재명 | D3: SIZE | E3: 칼라 | F3: 수량 | G3: 무게 | H3: 단가
A4: JT-1 | B4: BF6X27C51 | C4: 비침방지 | D4: 44" | E4: 1966 (ASH) | F4: 221 | G4: 68 | H4: 1600
A5: JT-2 | B5: BF6X27C51 | C5: 비침방지 | D5: 44" | E5: 1966 (ASH) | F5: 300 | G5: 68 | H5: 1600
A6: JT-3 | B6: BF6X27C51 | C6: 비침방지 | D6: 44" | E6: 1966 (ASH) | F6: 232 | G6: 68 | H6: 1600
A7: JT-4 | B7: BF6X27C51 | C7: 비침방지 | D7: 44" | E7: 1844-1 (브라운) | F7: 200 | G7: 68 | H7: 1600
A8: JT-5 | B8: BF6X27C51 | C8: 비침방지 | D8: 44" | E8: 1844-1 (브라운) | F8: 246 | G8: 68 | H8: 1600
A9: JT-6 | B9: BF6X21C62 | C9: 비침방지 | D9: 44" | E9: 1844-1 (브라운) | F9: 302 | G9: 68 | H9: 1600
A10: JT-7 | B10: BF6X21C62 | C10: 비침방지 | D10: 44" | E10: 1844-1 (브라운) | F10: 302 (중국) | G10: 68 | H10: 1600
A11: JT-8 | B11: BF6X21C63 | C11: 비침방지 | D11: 44" | E11: 1967(검) (ASH) | F11: 364 | G11: 68 | H11: 1600
A12: JT-9 | B12: BF6X21C62 | C12: T/C | D12: 44" | E12: 1179 (브라운) | F12: 76 | G12: 103 | H12: 1350
B13: BF6X21C52 | C13: T/C | D13: 44" | E13: 1005 (아이) | F13: 85 | G13: 103 | H13: 1350
A14: JT-10 | B14: BF6X21C52 | C14: T/C | D14: 44" | E14: BK | F14: 210 | G14: 103 | H14: 1350
A15: JT-11 | B15: BF6X21C51 | C15: T/C | D15: 44" | E15: BK | F15: 220 | G15: 103 | H15: 1350
A16: JT-12 | B16: BF6X21C52 | C16: T/C | D16: 44" | E16: 1351(검) (ASH) | F16: 252 | G16: 103 | H16: 1350
A17: JT-13 | B17: BF6X21C51 | C17: T/C | D17: 44" | E17: 1351(검) (브라운) | F17: 132 | G17: 103 | H17: 1350
A18: JT-14 | B18: BF6X21C51 | C18: T/C | D18: 44" | E18: 1351(검) (브라운) | F18: 45 (중국) | G18: 103 | H18: 1350
B19: BF6X21Y51 | C19: T/C | D19: 44" | E19: 1346 (네이비) | F19: 77 (중국) | G19: 103 | H19: 1350
B20: BF6X21C62 | C20: T/C | D20: 44" | E20: 1179 (브라운) | F20: 29 (중국) | G20: 103 | H20: 1350
A21: JT-15 | B21: BF6X27C51 | C21: 비침방지 | D21: 44" | E21: 1844-1 (브라운) | F21: 70 (중국) | G21: 68 | H21: 1600
C22: 비침방지 | D22: 44" | E22: 1966 (ASH) | F22: 140 (중국) | G22: 68 | H22: 1600
B23: BF6X21C52 | C23: T/C | D23: 44" | E23: 1351 (ASH) | F23: 53 (중국) | G23: 103 | H23: 1350
A24: JT-16 | B24: 356X11WC1 | C24: 투일 | D24: 60" | E24: BK | F24: 200 | G24: 102 | H24: 1400
A25: JT-17 | B25: 356X11WC1 | C25: 투일 | D25: 60" | E25: BK | F25: 200 | G25: 102 | H25: 1400
A26: JT-18 | B26: 356X11WC1 | C26: 투일 | D26: 60" | E26: BK | F26: 200 | G26: 102 | H26: 1400
A27: JT-19 | B27: 356X11WC1 | C27: 투일 | D27: 60" | E27: BK | F27: 200 | G27: 102 | H27: 1400
A28: JT-20 | B28: 356X11WC1 | C28: 투일 | D28: 60" | E28: BK (ASH) | F28: 200 | G28: 102 | H28: 1400
A29: JT-21 | B29: 356X11WC1 | C29: 투일 | D29: 60" | E29: BK (ASH) | F29: 200 | G29: 102 | H29: 1400
A30: JT-22 | B30: 356X11WC1 | C30: 투일 | D30: 60" | E30: BK (ASH) | F30: 175 | G30: 102 | H30: 1400
A31: JT-23 | B31: 356X11WC1 | C31: 투일 | D31: 60" | E31: BK | F31: 100 | G31: 102 | H31: 1400
A32: JT-24 | B32: 356X11WC1 | C32: 남자패드 | D32: 4mm | E32: BK | F32: 500 | G32: 17 | H32: 1000
A33: JT-25 | B33: 356X11WC1 | C33: 남자패드 | D33: 4mm | E33: BK | F33: 500 | G33: 17 | H33: 1000
A34: JT-26 | B34: 356X11WC1 | C34: 남자패드 | D34: 4mm | E34: BK | F34: 230 | G34: 17 | H34: 1000
A35: JT-27 | B35: BF6X21C51 | C35: 라이크라밴드 | D35: 38mm | E35: BK | F35: 19 | G35: 30 | H35: 600
A36: JT-28 | B36: KM269OPT006M | C36: T/C | D36: 44" | E36: 9036 (베이지) | F36: 109 | G36: 103 | H36: 1500
C37: T/C | D37: 44" | E37: 1277 (버건디) | F37: 53 | G37: 103 | H37: 1500
A38: JT-29 | B38: KM269OPT006M | C38: T/C | D38: 44" | E38: BK | F38: 142 | G38: 103 | H38: 1500
A39: JT-30 | B39: BF6X21C52 | C39: 에프론지퍼 | D39: 9" | E39: BK | F39: 2240 | G39: 6 | H39: 240
C40: 에프론지퍼 | D40: 9" | E40: 아이 | F40: 405 | G40: 6 | H40: 240
B41: BF6X21C63 | C41: 에프론지퍼 | D41: 9" | E41: BK | F41: 510 | G41: 6 | H41: 240
...

Sheet 아즈텍_중국분
B1: 출고송장 (260624-1002,상차-2) | BY1: 상 호 | CH1: (주)케이에스케이
A6: 매 출 처 | K6: 삼성물산패션부문 | AQ6: 오 다 량 | BA6: 1,780.00 Mts
BY7: 등록번호 | CH7: 134-81-40056 | DB7: 성 명 | DH7: 고한식
A9: 오다번호 스타일NO | K9: 4502904441_x000D_ BF6X27C51 | AQ9: 출 고 량 | BA9: 348.00 Mts
BY11: 주 소 | CH11: 경기도 시흥시 협력로 175 (정왕동, 시화공단1다 704)
A13: 품 명 | K13: F11-BF6C04 AW/98, PU/2 | AQ13: 오다/검사폭 | BA13: 133.00/133.00 Cm
A17: 바 이 어 | K17: 삼성물산패션부(빈폴레이디스 | AQ17: 포장방법 | BY17: 업 태 | CH17: 제조,부동산 | CU17: 종 목 | DB17: 정포임가공,임대
A20: 인 수 처 | K20: 태일무역 | AQ20: 출 고 일 | BA20: 2026-07-15 | BY20: 전화번호 | CH20: 031)499-6581~3 Fax : 031)499-6584
A23: 비 고 | K23: 금천구 가산디지털2로115 대륭3차715호 010-7771-1085 / 안산퀵/아즈텍청구 (0111) | DL23: Page : 1 / 1
A27: Color Name | AC27: Roll | AH27: Gross | AR27: Net | BB27: Loss | BI27: Weight
A30: 1 )4-ASH(재색) | AC30: 5 | AH30: 349 | AR30: 348 | BB30: 1 | BI30: 105.7
A33: T O T A L --> | AC33: 5 | AH33: 349 | AR33: 348 | BB33: 1 | BI33: 105.7
A36: Color Name | AC36: Roll | AH36: Gross | AR36: Net | BB36: Loss | BI36: Weight | BS36: CT/No | BZ36: R/No | CF36: Lot | CM36: Gross | CV36: Net | DE36: Loss | DL36: Grade | DQ36: Weight
A39: 1 )4-ASH(재색) | AC39: 5 | AH39: 349 | AR39: 348 | BB39: 1 | BI39: 105.7 | BZ39: 21 | CF39: 1 | CM39: 53 | CV39: 53 | DL39: A | DQ39: 16.1
BZ42: 22 | CF42: 1 | CM42: 34 | CV42: 34 | DL42: A | DQ42: 10.4
BZ45: 23 | CF45: 1 | CM45: 88 | CV45: 88 | DL45: A | DQ45: 26.4
BZ48: 24 | CF48: 1 | CM48: 87 | CV48: 86 | DE48: 1 | DL48: A | DQ48: 26.25
BZ51: 25 | CF51: 1 | CM51: 87 | CV51: 87 | DL51: A | DQ51: 26.55
A126: (주)유일전산 ☎ (02) 761-0758 섬유업체 S/W 개발전문업체 | BP126: 출력자 : 김정은 2026-07-15 오전 8:56:55

Sheet 봅_중국분1
B1: 마대 PACKING LIST (260609-1041,상차-1)
A6: SHIPPER | K6: 봅텍스타일 | AU6: ORDER Q'TY | BE6: 188.00 Mts
A9: ORDER NO STYLE NO | K9: BF6X21C62_x000D_ BTM2606-111 | AU9: S/Q'TY | BE9: 175.75 Mts
A13: ITEM | K13: WWA054KN 카도르 | AU13: WIDTH | BE13: 143.00/145.00 Cm
A17: BUYER | K17: 삼성물산(빈폴레이디스 | AU17: BOX SIZE | BE17: 마대-1800*450
A20: ATTN | K20: 태일무역 기성간실장님 | AU20: S/DATE | BE20: 2026-07-15
A23: REMARK | K23: 금천구 가산디지털2로 대륭테크노타운 3차 715호 010-7772-6918 / 안산퀵 | DL23: Page : 1 / 1
F27: Color Name | AH27: Roll | AM27: Gross | AX27: Net | BI27: Loss | BQ27: Weight
F30: 1 )BROWN_K00859 | AH30: 4 | AM30: 178 | AX30: 175.75 | BI30: 2.25 | BQ30: 53.1
F33: T O T A L --> | AH33: 4 | AM33: 178 | AX33: 175.75 | BI33: 2.25 | BQ33: 53.1
A36: B/No | F36: Color Name | AH36: Roll | AM36: Gross | AX36: Net | BI36: Loss | BQ36: Weight | CB36: R/No | CH36: Lot | CO36: Gross | CW36: Net | DE36: Loss | DL36: Grade | DQ36: Weight
A39: BOB-1 | F39: 1 )BROWN_K00859 | AH39: 1 | AM39: 55 | AX39: 53.25 | BI39: 1.75 | BQ39: 16.7 | CB39: 4 | CH39: 1 | CO39: 55 | CW39: 53.25 | DE39: 1.75 | DL39: A | DQ39: 16.7
F42: Box Total --> | AH42: 1 | AM42: 55 | AX42: 53.25 | BI42: 1.75 | BQ42: 16.7
A45: 2 | F45: 1 )BROWN_K00859 | AH45: 1 | AM45: 50 | AX45: 50 | BQ45: 15.35 | CB45: 3 | CH45: 1 | CO45: 50 | CW45: 50 | DL45: A | DQ45: 15.35
F48: Box Total --> | AH48: 1 | AM48: 50 | AX48: 50 | BQ48: 15.35
A51: 3 | F51: 1 )BROWN_K00859 | AH51: 2 | AM51: 73 | AX51: 72.5 | BI51: 0.5 | BQ51: 21.05 | CB51: 1 | CH51: 1 | CO51: 22 | CW51: 22 | DL51: A | DQ51: 7.7
CB54: 2 | CH54: 1 | CO54: 51 | CW54: 50.5 | DE54: 0.5 | DL54: A | DQ54: 13.35
F57: Box Total --> | AH57: 2 | AM57: 73 | AX57: 72.5 | BI57: 0.5 | BQ57: 21.05
F60: Box Count ==> | AH60: 3
A126: (주)유일전산 ☎ (02) 761-0758 섬유업체 S/W 개발전문업체 | BP126: 출력자 : 장영옥과장 2026-07-14 오전 9:23:26

Sheet 봅_중국분2
B1: 마대 PACKING LIST (260529-1003,상차-1)
A6: SHIPPER | K6: 봅텍스타일 | AU6: ORDER Q'TY | BE6: 129.00 Mts
A9: ORDER NO STYLE NO | K9: BTM2605-297 | AU9: S/Q'TY | BE9: 129.75 Mts
A13: ITEM | K13: WWA054KN 카도르 | AU13: WIDTH | BE13: 143.00/146.00 Inch
A17: BUYER | K17: 삼성물산(빈폴레이디스 | AU17: BOX SIZE | BE17: 마대-1800*450
A20: ATTN | K20: 태일무역 기성간실장님 | AU20: S/DATE | BE20: 2026-07-15
A23: REMARK | K23: 금천구 가산디지털2로 대륭테크노타운 3차 715호 010-7772-6918 / 안산퀵 | DL23: Page : 1 / 1
F27: Color Name | AH27: Roll | AM27: Gross | AX27: Net | BI27: Loss | BQ27: Weight
F30: 1 )PHANTOM-M | AH30: 3 | AM30: 131 | AX30: 129.75 | BI30: 1.25 | BQ30: 40.3
F33: T O T A L --> | AH33: 3 | AM33: 131 | AX33: 129.75 | BI33: 1.25 | BQ33: 40.3
A36: B/No | F36: Color Name | AH36: Roll | AM36: Gross | AX36: Net | BI36: Loss | BQ36: Weight | CB36: R/No | CH36: Lot | CO36: Gross | CW36: Net | DE36: Loss | DL36: Grade | DQ36: Weight
A39: BOB-4 | F39: 1 )PHANTOM-M | AH39: 1 | AM39: 39 | AX39: 38 | BI39: 1 | BQ39: 12.15 | CB39: 3 | CH39: 1 | CO39: 39 | CW39: 38 | DE39: 1 | DL39: A | DQ39: 12.15
F42: Box Total --> | AH42: 1 | AM42: 39 | AX42: 38 | BI42: 1 | BQ42: 12.15
A45: 5 | F45: 1 )PHANTOM-M | AH45: 1 | AM45: 48 | AX45: 47.75 | BI45: 0.25 | BQ45: 14.7 | CB45: 2 | CH45: 1 | CO45: 48 | CW45: 47.75 | DE45: 0.25 | DL45: A | DQ45: 14.7
F48: Box Total --> | AH48: 1 | AM48: 48 | AX48: 47.75 | BI48: 0.25 | BQ48: 14.7
A51: 6 | F51: 1 )PHANTOM-M | AH51: 1 | AM51: 44 | AX51: 44 | BQ51: 13.45 | CB51: 1 | CH51: 1 | CO51: 44 | CW51: 44 | DL51: A | DQ51: 13.45
F54: Box Total --> | AH54: 1 | AM54: 44 | AX54: 44 | BQ54: 13.45
F57: Box Count ==> | AH57: 3
A126: (주)유일전산 ☎ (02) 761-0758 섬유업체 S/W 개발전문업체 | BP126: 출력자 : 장영옥과장 2026-07-14 오전 9:24:44

Sheet MATERIAL PACKING LIST 06-01 (5)
A1: Material Actual Packing List
G3: <SHIP 선적일> : 2026년 7月17日
G5: SHIP 선적지 : 한국 태일무역
G6: SHIP 도착지 : 베트남 태일비나
A8: CT / No. | B8: Style No. | C8: Color | D8: Size | E8: R/NO | F8: LOT | G8: Q`ty | H8: Item | I8: Kg | J8: 단가
A9: T.I-274 | B9: BF6X21C52 | C9: 4 | G9: 250 | H9: 중국분 메인라벨
B10: BF6X27C51 | C10: 4 | G10: 215
B11: BF6X27C51 | C11: D | G11: 110
B12: BF6X21C51 | C12: 5 | G12: 975 | H12: 국내분 메인라벨
B13: BF6X21C52 | C13: 0 | G13: 396
C14: 4 | G14: 1208
C15: 5 | G15: 1023
B16: BF6X27C51 | C16: 4 | G16: 1075
B17: BF6X27C51 | C17: D | G17: 637
B18: BF6X21C51 | C18: 5 | G18: 1007 | H18: 케어라벨
C19: 5 | G19: 1007 | H19: 가격택
B20: BF6X21C52 | C20: 0 | G20: 410 | H20: 케어라벨
C21: 0 | G21: 410 | H21: 가격택
C22: 4 | G22: 1245 | H22: 케어라벨
C23: 4 | G23: 1245 | H23: 가격택
C24: 5 | G24: 1055 | H24: 케어라벨
C25: 5 | G25: 1055 | H25: 가격택
B26: BF6X21E12 | C26: NAVY | D26: 15MM | G26: 1570 | H26: 단추 | J26: 140
C27: BROWN | D27: 15MM | G27: 1840
A28: T.I-275 | B28: 356911CC3 | C28: BROWN | D28: 23MM | G28: 1620 | H28: 단추 | I28: 3 | J28: 53
C29: BLACK | D29: 9MM | G29: 1620 | J29: 10
B30: 356X11WC1 | C30: BLACK | D30: 20MM | G30: 7300 | H30: 단추 | J30: 70
A31: T.I-276 | B31: KM269OPT006M | C31: BLACK | E31: 6 | G31: 35 | H31: 원단
A32: T.I-277 | E32: 9 | G32: 30
A33: T.I-278 | E33: 14 | G33: 32
A34: T.I-279 | E34: 11 | G34: 37
A35: T.I-280 | E35: 5 | G35: 30
A36: T.I-281 | E36: 2 | G36: 32
A37: T.I-282 | E37: 13 | G37: 29
A38: T.I-283 | E38: 10 | G38: 24
A39: T.I-284 | E39: 7 | G39: 37
A40: T.I-285 | E40: 8 | G40: 26
A41: T.I-286 | E41: 1 | G41: 26
A42: T.I-287 | E42: 4 | G42: 41
A43: T.I-288 | E43: 3 | G43: 27
...
